Workbook

Sheet Statistical_Summary
A1: Statistical Summary - Week 6 EDA
A2: Dataset: Final_Clean_Dataset.csv | Sumber kolom: Raw_Data sheet
A4: A. Job_Description_Length
A5: Statistik | B5: Nilai
A6: Count | B6: =COUNT(Raw_Data!A2:A19963) -> 19962
A7: Mean | B7: =AVERAGE(Raw_Data!A2:A19963) -> 2479.7648
A8: Median | B8: =MEDIAN(Raw_Data!A2:A19963) -> 2195.5
A9: Modus | B9: =MODE(Raw_Data!A2:A19963) -> 2490
A10: Minimum | B10: =MIN(Raw_Data!A2:A19963) -> 16
A11: Maksimum | B11: =MAX(Raw_Data!A2:A19963) -> 20189
A12: Standar Deviasi | B12: =STDEV(Raw_Data!A2:A19963) -> 1607.3453
A13: Q1 (25%) | B13: =QUARTILE(Raw_Data!A2:A19963,1) -> 1363
A14: Q2 / Median (50%) | B14: =QUARTILE(Raw_Data!A2:A19963,2) -> 2195.5
A15: Q3 (75%) | B15: =QUARTILE(Raw_Data!A2:A19963,3) -> 3259
A17: B. Cleaned_Salary (estimasi gaji tahunan, hasil pembersihan kolom Salary)
A18: Statistik | B18: Nilai
A19: Count (data valid) | B19: =COUNT(Raw_Data!B2:B19963) -> 2671
A20: Mean | B20: =AVERAGE(Raw_Data!B2:B19963) -> 35353.487
A21: Median | B21: =MEDIAN(Raw_Data!B2:B19963) -> 35000
A22: Modus | B22: =IFERROR(MODE(Raw_Data!B2:B19963),"Tidak ada modus") -> 40000
A23: Minimum | B23: =MIN(Raw_Data!B2:B19963) -> 0
A24: Maksimum | B24: =MAX(Raw_Data!B2:B19963) -> 850000
A25: Standar Deviasi | B25: =STDEV(Raw_Data!B2:B19963) -> 40663.323
A26: Q1 (25%) | B26: =QUARTILE(Raw_Data!B2:B19963,1) -> 16
A27: Q2 / Median (50%) | B27: =QUARTILE(Raw_Data!B2:B19963,2) -> 35000
A28: Q3 (75%) | B28: =QUARTILE(Raw_Data!B2:B19963,3) -> 60000
A30: Catatan:
A31: Hanya sekitar 13-15% dari total data (Salary) yang berhasil dikonversi menjadi angka numerik oleh fungsi clean_salary() pada notebook, karena sebagian besar entri berupa 'Not Disclosed' atau deskripsi kualitatif seperti 'Commensurate with Experience'. Statistik gaji di atas hanya mewakili subset data yang berhasil dibersihkan.

Sheet Job_Type_Counts
A1: value_counts() - Job_Type
A2: Jumlah lowongan berdasarkan jenis pekerjaan
A4: Job_Type | B4: Jumlah | C4: Persentase
A5: Full Time | B5: =COUNTIF(Raw_Data!C2:C19963,A5) -> 17166 | C5: =B5/COUNTA(Raw_Data!C2:C19963) -> 0.85993387
A6: Contract/Temporary | B6: =COUNTIF(Raw_Data!C2:C19963,A6) -> 1762 | C6: =B6/COUNTA(Raw_Data!C2:C19963) -> 0.088267709
A7: Part Time | B7: =COUNTIF(Raw_Data!C2:C19963,A7) -> 813 | C7: =B7/COUNTA(Raw_Data!C2:C19963) -> 0.040727382
A8: Other | B8: =COUNTIF(Raw_Data!C2:C19963,A8) -> 148 | C8: =B8/COUNTA(Raw_Data!C2:C19963) -> 0.0074140868
A9: Per Diem | B9: =COUNTIF(Raw_Data!C2:C19963,A9) -> 65 | C9: =B9/COUNTA(Raw_Data!C2:C19963) -> 0.0032561868
A10: Intern | B10: =COUNTIF(Raw_Data!C2:C19963,A10) -> 8 | C10: =B10/COUNTA(Raw_Data!C2:C19963) -> 0.00040076145

Sheet Location_Counts
A1: value_counts() - Location (Top 20)
A2: 20 lokasi kerja dengan jumlah lowongan terbanyak
A4: Location | B4: Jumlah
A5: Dallas, TX | B5: =COUNTIF(Raw_Data!D2:D19963,A5) -> 556
A6: Cincinnati, OH | B6: =COUNTIF(Raw_Data!D2:D19963,A6) -> 304
A7: Dallas, TX 75201 | B7: =COUNTIF(Raw_Data!D2:D19963,A7) -> 266
A8: Columbus, OH | B8: =COUNTIF(Raw_Data!D2:D19963,A8) -> 220
A9: Houston, TX | B9: =COUNTIF(Raw_Data!D2:D19963,A9) -> 186
A10: Atlanta, GA | B10: =COUNTIF(Raw_Data!D2:D19963,A10) -> 155
A11: Location: | B11: =COUNTIF(Raw_Data!D2:D19963,A11) -> 131
A12: Austin, TX | B12: =COUNTIF(Raw_Data!D2:D19963,A12) -> 133
A13: Columbus, OH 43215 | B13: =COUNTIF(Raw_Data!D2:D19963,A13) -> 121
A14: Chicago, IL | B14: =COUNTIF(Raw_Data!D2:D19963,A14) -> 116
A15: Las Vegas, NV | B15: =COUNTIF(Raw_Data!D2:D19963,A15) -> 107
A16: San Antonio, TX | B16: =COUNTIF(Raw_Data!D2:D19963,A16) -> 96
A17: Boston, MA | B17: =COUNTIF(Raw_Data!D2:D19963,A17) -> 91
A18: Madison, WI | B18: =COUNTIF(Raw_Data!D2:D19963,A18) -> 89
A19: Cincinnati, OH 45202 | B19: =COUNTIF(Raw_Data!D2:D19963,A19) -> 82
A20: Chicago, IL 60603 | B20: =COUNTIF(Raw_Data!D2:D19963,A20) -> 81
A21: Denver, CO | B21: =COUNTIF(Raw_Data!D2:D19963,A21) -> 74
A22: Las Vegas, NV 89119 | B22: =COUNTIF(Raw_Data!D2:D19963,A22) -> 62
A23: Irving, TX | B23: =COUNTIF(Raw_Data!D2:D19963,A23) -> 62
A24: Knoxville, TN | B24: =COUNTIF(Raw_Data!D2:D19963,A24) -> 59

Sheet Job_Title_Counts
A1: value_counts() - Job_Title (Top 20)
A2: 20 judul pekerjaan dengan jumlah lowongan terbanyak
A4: Job_Title | B4: Jumlah
A5: Monster | B5: =COUNTIF(Raw_Data!E2:E19963,A5) -> 292
A6: Manager | B6: =COUNTIF(Raw_Data!E2:E19963,A6) -> 48
A7: Please Apply Only If You Are Qualified. | B7: =COUNTIF(Raw_Data!E2:E19963,A7) -> 29
A8: Director | B8: =COUNTIF(Raw_Data!E2:E19963,A8) -> 22
A9: Rn | B9: =COUNTIF(Raw_Data!E2:E19963,A9) -> 18
A10: Truck Driver – Entry Level ( Cdl Not Required ) Transportation – Full Time | B10: =COUNTIF(Raw_Data!E2:E19963,A10) -> 17
A11: Manufacturing – Change Career To - Truck Driver – Entry Level | B11: =COUNTIF(Raw_Data!E2:E19963,A11) -> 16
A12: Senior Manager | B12: =COUNTIF(Raw_Data!E2:E19963,A12) -> 13
A13: Staff Accountant Job In Dallas | B13: =COUNTIF(Raw_Data!E2:E19963,A13) -> 12
A14: Recruiter | B14: =COUNTIF(Raw_Data!E2:E19963,A14) -> 11
A15: Financial Advisor / Financial Sales Representative- Full Time Sales | B15: =COUNTIF(Raw_Data!E2:E19963,A15) -> 10
A16: Analyst | B16: =COUNTIF(Raw_Data!E2:E19963,A16) -> 9
A17: Supervisor | B17: =COUNTIF(Raw_Data!E2:E19963,A17) -> 9
A18: Associate Director | B18: =COUNTIF(Raw_Data!E2:E19963,A18) -> 8
A19: Senior Accountant Job In Dallas | B19: =COUNTIF(Raw_Data!E2:E19963,A19) -> 8
A20: Sales Representative Job In Dallas | B20: =COUNTIF(Raw_Data!E2:E19963,A20) -> 8
A21: Truck Drivers - No Cdl? No Problem! We Train | B21: =COUNTIF(Raw_Data!E2:E19963,A21) -> 8
A22: Resident Care Specialist | B22: =COUNTIF(Raw_Data!E2:E19963,A22) -> 7
A23: Vp | B23: =COUNTIF(Raw_Data!E2:E19963,A23) -> 7
A24: Registered Nurse | B24: =COUNTIF(Raw_Data!E2:E19963,A24) -> 7

Sheet Organization_Counts
A1: value_counts() - Organization (Top 20)
A2: 20 organisasi/perusahaan dengan jumlah lowongan terbanyak
A4: Organization | B4: Jumlah
A5: Healthcare Services | B5: =COUNTIF(Raw_Data!F2:F19963,A5) -> 8072
A6: All | B6: =COUNTIF(Raw_Data!F2:F19963,A6) -> 1069
A7: Other/Not Classified | B7: =COUNTIF(Raw_Data!F2:F19963,A7) -> 951
A8: Manufacturing - Other | B8: =COUNTIF(Raw_Data!F2:F19963,A8) -> 835
A9: Computer/IT Services | B9: =COUNTIF(Raw_Data!F2:F19963,A9) -> 779
A10: Retail | B10: =COUNTIF(Raw_Data!F2:F19963,A10) -> 534
A11: Legal Services | B11: =COUNTIF(Raw_Data!F2:F19963,A11) -> 459
A12: Business Services - Other | B12: =COUNTIF(Raw_Data!F2:F19963,A12) -> 395
A13: Restaurant/Food Services | B13: =COUNTIF(Raw_Data!F2:F19963,A13) -> 367
A14: Food and Beverage Production | B14: =COUNTIF(Raw_Data!F2:F19963,A14) -> 320
A15: Transport and Storage - Materials | B15: =COUNTIF(Raw_Data!F2:F19963,A15) -> 313
A16: Insurance | B16: =COUNTIF(Raw_Data!F2:F19963,A16) -> 304
A17: Construction - Industrial Facilities and Infrastructure | B17: =COUNTIF(Raw_Data!F2:F19963,A17) -> 287
A18: Accounting and Auditing Services | B18: =COUNTIF(Raw_Data!F2:F19963,A18) -> 266
A19: Biotechnology/Pharmaceuticals | B19: =COUNTIF(Raw_Data!F2:F19963,A19) -> 242
A20: Education | B20: =COUNTIF(Raw_Data!F2:F19963,A20) -> 232
A21: Real Estate/Property Management | B21: =COUNTIF(Raw_Data!F2:F19963,A21) -> 215
A22: Staffing/Employment Agencies | B22: =COUNTIF(Raw_Data!F2:F19963,A22) -> 213
A23: Computer Software | B23: =COUNTIF(Raw_Data!F2:F19963,A23) -> 155
A24: Banking | B24: =COUNTIF(Raw_Data!F2:F19963,A24) -> 147

Sheet Salary_Category_Counts
A1: Distribusi Kategori Gaji (Salary_Category)
A2: Berdasarkan Cleaned_Salary yang dikelompokkan ke dalam rentang
A4: Kategori Gaji | B4: Jumlah | C4: Persentase
A5: <$40K | B5: =COUNTIF(Raw_Data!H2:H19963,A5) -> 1578 | C5: =B5/COUNT(Raw_Data!B2:B19963) -> 0.59078997
A6: $40K-$60K | B6: =COUNTIF(Raw_Data!H2:H19963,A6) -> 476 | C6: =B6/COUNT(Raw_Data!B2:B19963) -> 0.17821041
A7: $60K-$80K | B7: =COUNTIF(Raw_Data!H2:H19963,A7) -> 373 | C7: =B7/COUNT(Raw_Data!B2:B19963) -> 0.13964807
A8: $80K-$100K | B8: =COUNTIF(Raw_Data!H2:H19963,A8) -> 244 | C8: =B8/COUNT(Raw_Data!B2:B19963) -> 0.091351554
A9: $100K-$120K | B9: =COUNTIF(Raw_Data!H2:H19963,A9) -> 97 | C9: =B9/COUNT(Raw_Data!B2:B19963) -> 0.036315987
A10: $120K-$150K | B10: =COUNTIF(Raw_Data!H2:H19963,A10) -> 38 | C10: =B10/COUNT(Raw_Data!B2:B19963) -> 0.014226881
A11: $150K-$200K | B11: =COUNTIF(Raw_Data!H2:H19963,A11) -> 18 | C11: =B11/COUNT(Raw_Data!B2:B19963) -> 0.006739049
A12: $200K+ | B12: =COUNTIF(Raw_Data!H2:H19963,A12) -> 5 | C12: =B12/COUNT(Raw_Data!B2:B19963) -> 0.0018719581

Sheet Avg_Salary_by_Group
A1: Rata-rata Gaji Tertinggi per Kelompok
A2: Hanya kelompok dengan lebih dari 5 entri gaji bersih (Cleaned_Salary)
A4: 1. Top 10 Job_Title dengan Rata-rata Gaji Tertinggi
A5: Tidak ada Job_Title dengan lebih dari 5 entri gaji bersih pada dataset ini.
A7: 2. Top 10 Organization dengan Rata-rata Gaji Tertinggi
A8: Organization | B8: Rata-rata Gaji | C8: Jumlah Entri
A9: Architectural and Design Services | B9: =AVERAGEIF(Raw_Data!F2:F19963,A9,Raw_Data!B2:B19963) -> 61848.667 | C9: =COUNTIFS(Raw_Data!F2:F19963,A9,Raw_Data!B2:B19963,"<>") -> 6
A10: Construction - Industrial Facilities and Infrastructure | B10: =AVERAGEIF(Raw_Data!F2:F19963,A10,Raw_Data!B2:B19963) -> 56821.909 | C10: =COUNTIFS(Raw_Data!F2:F19963,A10,Raw_Data!B2:B19963,"<>") -> 22
A11: Construction - Residential & Commercial/Office | B11: =AVERAGEIF(Raw_Data!F2:F19963,A11,Raw_Data!B2:B19963) -> 53088.913 | C11: =COUNTIFS(Raw_Data!F2:F19963,A11,Raw_Data!B2:B19963,"<>") -> 46
A12: Computer Software | B12: =AVERAGEIF(Raw_Data!F2:F19963,A12,Raw_Data!B2:B19963) -> 52834.207 | C12: =COUNTIFS(Raw_Data!F2:F19963,A12,Raw_Data!B2:B19963,"<>") -> 23
A13: Automotive and Parts Mfg | B13: =AVERAGEIF(Raw_Data!F2:F19963,A13,Raw_Data!B2:B19963) -> 49327.915 | C13: =COUNTIFS(Raw_Data!F2:F19963,A13,Raw_Data!B2:B19963,"<>") -> 31
A14: Engineering Services | B14: =AVERAGEIF(Raw_Data!F2:F19963,A14,Raw_Data!B2:B19963) -> 45097.308 | C14: =COUNTIFS(Raw_Data!F2:F19963,A14,Raw_Data!B2:B19963,"<>") -> 13
A15: Healthcare Services | B15: =AVERAGEIF(Raw_Data!F2:F19963,A15,Raw_Data!B2:B19963) -> 42281.271 | C15: =COUNTIFS(Raw_Data!F2:F19963,A15,Raw_Data!B2:B19963,"<>") -> 1052
A16: Medical Devices and Supplies | B16: =AVERAGEIF(Raw_Data!F2:F19963,A16,Raw_Data!B2:B19963) -> 42094.636 | C16: =COUNTIFS(Raw_Data!F2:F19963,A16,Raw_Data!B2:B19963,"<>") -> 11
A17: Computer/IT Services | B17: =AVERAGEIF(Raw_Data!F2:F19963,A17,Raw_Data!B2:B19963) -> 40856.033 | C17: =COUNTIFS(Raw_Data!F2:F19963,A17,Raw_Data!B2:B19963,"<>") -> 61
A18: AllBusiness Services - Other | B18: =AVERAGEIF(Raw_Data!F2:F19963,A18,Raw_Data!B2:B19963) -> 40000 | C18: =COUNTIFS(Raw_Data!F2:F19963,A18,Raw_Data!B2:B19963,"<>") -> 26
A20: 3. Top 10 Location_State dengan Rata-rata Gaji Tertinggi
A21: Location_State | B21: Rata-rata Gaji | C21: Jumlah Entri
A22: MA | B22: =AVERAGEIF(Raw_Data!G2:G19963,A22,Raw_Data!B2:B19963) -> 60914.858 | C22: =COUNTIFS(Raw_Data!G2:G19963,A22,Raw_Data!B2:B19963,"<>") -> 155
A23: VA | B23: =AVERAGEIF(Raw_Data!G2:G19963,A23,Raw_Data!B2:B19963) -> 52896.911 | C23: =COUNTIFS(Raw_Data!G2:G19963,A23,Raw_Data!B2:B19963,"<>") -> 36
A24: AL | B24: =AVERAGEIF(Raw_Data!G2:G19963,A24,Raw_Data!B2:B19963) -> 48894.556 | C24: =COUNTIFS(Raw_Data!G2:G19963,A24,Raw_Data!B2:B19963,"<>") -> 18
A25: RI | B25: =AVERAGEIF(Raw_Data!G2:G19963,A25,Raw_Data!B2:B19963) -> 47505.929 | C25: =COUNTIFS(Raw_Data!G2:G19963,A25,Raw_Data!B2:B19963,"<>") -> 8
A26: DC | B26: =AVERAGEIF(Raw_Data!G2:G19963,A26,Raw_Data!B2:B19963) -> 46524.814 | C26: =COUNTIFS(Raw_Data!G2:G19963,A26,Raw_Data!B2:B19963,"<>") -> 17
A27: MD | B27: =AVERAGEIF(Raw_Data!G2:G19963,A27,Raw_Data!B2:B19963) -> 45152.464 | C27: =COUNTIFS(Raw_Data!G2:G19963,A27,Raw_Data!B2:B19963,"<>") -> 22
A28: CT | B28: =AVERAGEIF(Raw_Data!G2:G19963,A28,Raw_Data!B2:B19963) -> 43899.222 | C28: =COUNTIFS(Raw_Data!G2:G19963,A28,Raw_Data!B2:B19963,"<>") -> 9
A29: NJ | B29: =AVERAGEIF(Raw_Data!G2:G19963,A29,Raw_Data!B2:B19963) -> 43044.227 | C29: =COUNTIFS(Raw_Data!G2:G19963,A29,Raw_Data!B2:B19963,"<>") -> 82
A30: UT | B30: =AVERAGEIF(Raw_Data!G2:G19963,A30,Raw_Data!B2:B19963) -> 41121.34 | C30: =COUNTIFS(Raw_Data!G2:G19963,A30,Raw_Data!B2:B19963,"<>") -> 9
A31: LA | B31: =AVERAGEIF(Raw_Data!G2:G19963,A31,Raw_Data!B2:B19963) -> 40337.634 | C31: =COUNTIFS(Raw_Data!G2:G19963,A31,Raw_Data!B2:B19963,"<>") -> 18

Sheet High_Salary_200K_Plus
A1: Kombinasi Paling Sering pada Kategori Gaji $200K+
A2: Job_Title, Organization, dan Location_State yang paling sering muncul di kategori gaji tertinggi
A4: 1. Job_Title paling sering muncul (kategori $200K+)
A5: Job_Title | B5: Jumlah
A6: Team Lead Healthcare Analyst Job In Boston | B6: =COUNTIFS(Raw_Data!E2:E19963,A6,Raw_Data!H2:H19963,"$200K+") -> 1
A7: Medical Affairs Director - Infectious Diseases & Immunology Job In Madison | B7: =COUNTIFS(Raw_Data!E2:E19963,A7,Raw_Data!H2:H19963,"$200K+") -> 1
A8: General Dentist Job In Greenville | B8: =COUNTIFS(Raw_Data!E2:E19963,A8,Raw_Data!H2:H19963,"$200K+") -> 1
A9: Neurologist Job In Fort Bragg | B9: =COUNTIFS(Raw_Data!E2:E19963,A9,Raw_Data!H2:H19963,"$200K+") -> 1
A10: Global Medical Affairs Director - Solid Tumor Therapeutics Job In Northbrook | B10: =COUNTIFS(Raw_Data!E2:E19963,A10,Raw_Data!H2:H19963,"$200K+") -> 1
A12: 2. Organization paling sering muncul (kategori $200K+)
A13: Organization | B13: Jumlah
A14: Healthcare Services | B14: =COUNTIFS(Raw_Data!F2:F19963,A14,Raw_Data!H2:H19963,"$200K+") -> 5
A16: 3. Location_State paling sering muncul (kategori $200K+)
A17: Location_State | B17: Jumlah
A18: MA | B18: =COUNTIFS(Raw_Data!G2:G19963,A18,Raw_Data!H2:H19963,"$200K+") -> 1
A19: WI | B19: =COUNTIFS(Raw_Data!G2:G19963,A19,Raw_Data!H2:H19963,"$200K+") -> 1
A20: SC | B20: =COUNTIFS(Raw_Data!G2:G19963,A20,Raw_Data!H2:H19963,"$200K+") -> 1
A21: NC | B21: =COUNTIFS(Raw_Data!G2:G19963,A21,Raw_Data!H2:H19963,"$200K+") -> 1
A22: IL | B22: =COUNTIFS(Raw_Data!G2:G19963,A22,Raw_Data!H2:H19963,"$200K+") -> 1

Sheet Raw_Data
A1: Job_Description_Length | B1: Cleaned_Salary | C1: Job_Type | D1: Location | E1: Job_Title | F1: Organization | G1: Location_State | H1: Salary_Category
A2: 2794 | C2: Full Time | D2: Madison, WI 53702 | E2: It Support Technician Job In Madison | F2: Healthcare Services | G2: WI
A3: 1024 | C3: Full Time | D3: Madison, WI 53708 | E3: Business Reporter/Editor Job In Madison | F3: Printing and Publishing | G3: WI
A4: 5518 | C4: Full Time | D4: DePuy Synthes Companies is a member of Johnson & Johnson's Family of Companies, and is recruiting for a Senior Training Leader located in Raynham, MA.DePuy Synthes Companies of Johnson & Johnson is the largest, most innovative and comprehensive orthopedic and neurological business in the world. DePuy Synthes Companies offer an unparalleled breadth and depth of products, services and programs in the areas of joint reconstruction, trauma, spine, sports medicine, neurological, craniomaxillofacial, power tools and biomaterials. Building on the legacy and strengths of two great companies, more agile and better equipped to meet the needs of today’s evolving health care environment. With a focus on activating insights to develop innovative, comprehensive solutions, we are inspired to advance patient care in greater ways than either company could accomplish on its own.Position Overview• The Training Leader leads the site training function to develop and implement training programs that support company objectives and meet regulations. Directs staff in the design and administration of training programs to train all levels of personnel. Keep abreast of training and development research, new materials, methods and techniques. Develops programs and practices to identify developmental needs and monitor trends. Prepares personnel to increase effectiveness in present assignments and assume more responsibilities. Major Responsibilities & Duties:• Consults with management, employees, and departments to identify training needs, address them and achieve the end result of effective training solutions. • Recommends the creation or acquisition and delivery of training programs that meet the company's needs.• Implements training metrics to monitor training effectiveness against needs of the business. • Summarizes training program assessment data and participant attendance reports and submits or presents to management. • Supervises, coaches and develops assigned personnel. • Ensures that all assigned personnel have the education, training and experience, or a combination of these, in order to carry out all job duties and responsibilities.• Creates new training materials as required in collaboration with subject matter experts. • Communicates and escalates issues to the next management level as needed • Develops and maintains a training program to support the company needs and meet applicable local, federal and state laws/regulations.• As applicable is responsible for the site implementation of TWI (Training within Industry) methodology and others directed towards optimizing training practices across all operational areas. • Experience as subject matter trainer to conduct training sessions i.e. quality system related topics and to certify employees as trainers across the company. • Knowledge in Learning Management System (LMS) and its use to deploy training programs and requirements across the company. • Understands basic finance management to support managing site training budgets and capital projects if needed. • Application of Basic Project Management and/or Process Excellence knowledge and skills• Reviews, interprets and explains documents such as technical data, safety rules, operating and maintenance instructions, and procedure manuals. • Leads projects of moderate to high complexity• Performs any other task as required by Training ManagerQualifications• A minimum of a Bachelors Degree is required in Business, Education, Industrial Engineering or other related technical field. • 4 + years relevant working experience in training positions is required • A minimum of 2 years of people management experience is required• Experience working in an FDA and/or European regulatory environment is preferred. • This position will require relevant experience working in manufacturing/operations or R&D/new product development. • Proven experience designing and presenting successful training programs. • Ability to clarify and summarize regulatory documents into formats to execute trainings• Certified in TWI (Training within Industry Methodology) is preferred• ASQ (American Society for Quality)/ PE (Process Excellence) or equivalent certifications are preferred • A thorough understanding of GMP (Good Manufacturing Practices)/ISO (International Organization for Standardization) regulations is preferred. • Strong leadership and coaching skills are required. • Demonstrated project management abilities are required.• Excellent communication skills• Proficient in Microsoft Office —Word, Excel, and PowerPoint• This position may require up to 10% travel and will be based in Raynham, MA.BE VITAL in your career. Be seen for the talent you bring to your work. Explore opportunities within the Johnson & Johnson Family of Companies.Primary LocationUnited States-Massachusetts-RaynhamOrganizationDepuy Orthopaedics. Inc. (6029)Job FunctionQuality (Generalist) | E4: Johnson & Johnson Family Of Companies Job Application For Senior Training Leader | Monster.Com Var Mons_Log_Vars = {"Jobid": | F4: Personal and Household Services | G4: MA
A5: 5884 | C5: Full Time | D5: Dixon, CA | E5: Engineer - Quality Job In Dixon | F5: Altec Industries | G5: CA
A6: 7329 | C6: Full Time | D6: Camphill, PA | E6: Shift Supervisor - Part-Time Job In Camphill | F6: Retail | G6: PA
A7: 1724 | C7: Full Time | D7: Charlottesville, VA | E7: Construction Pm - Charlottesville Job In Charlottesville | F7: Computer/IT Services | G7: VA
A8: 1706 | C8: Full Time | D8: Contact name Tony Zerio | E8: Cybercoders Job Application For Principal Qa Engineer - Java | F8: Computer Software
A9: 2394 | C9: Full Time | D9: Austin, TX 73301 | E9: Mailroom Clerk Job In Austin | F9: Healthcare Services | G9: TX
A10: 1543 | C10: Part Time | D10: Austin, TX 78746 | E10: Housekeeper Job In Austin | F10: Hotels and Lodging Personal and Household Services | G10: TX
A11: 3683 | C11: Full Time | D11: Chesterfield, MO | E11: Video Data Management /Transportation Technician Job In Chesterfield | F11: Healthcare Services | G11: MO
A12: 4363 | C12: Full Time | D12: Berryville, VA 22611 | E12: Aflac Insurance Sales Agent Job In Berryville | F12: Insurance | G12: VA
A13: 1061 | C13: Full Time | D13: Columbus, IN | E13: Sales Associate Job In Columbus | F13: Business Services - Other | G13: IN
A14: 1689 | C14: Full Time | D14: Boston, MA | E14: Junior Proofreader Job In Boston | F14: Healthcare Services | G14: MA
A15: 2279 | B15: 9 | C15: Full Time | D15: Houston, TX 77098 | E15: Primrose Private Preschool Teacher Job In Houston | F15: Education | G15: TX | H15: <$40K
A16: 1609 | B16: 80000 | C16: Full Time | D16: Houston, TX | E16: Superintendent Job In Houston | F16: Construction - Industrial Facilities and InfrastructureConstruction - Residential & Commercial/Office | G16: TX | H16: $80K-$100K
A17: 3834 | C17: Full Time | D17: Des Moines, IA 50317 | E17: Engineer Ii - Outside Plant Engineer Job In Des Moines | F17: Healthcare Services | G17: IA
A18: 2200 | C18: Full Time | D18: Wadesboro 28170 | E18: Horizontal Construction Engineers Job In Wadesboro Body { Margin:Px; Overflow: Visible !Important; } #Ejb_Header { Color: #; Font-Family: Verdana | F18: Healthcare Services
A19: 4856 | C19: Full Time | D19: Denver, CO | E19: Pest Control Technician – Field Service Rep (Entry Level) Job In Denver | F19: Accounting and Auditing Services | G19: CO
A20: 3393 | C20: Full Time | D20: Natick, MA | E20: Content Developer For Matlab Code Generation Job In Natick | F20: Education | G20: MA
A21: 4340 | B21: 60000 | C21: Full Time | D21: Carter Lake, IA 51510 | E21: Technician - Robot & Multi-Axis Cnc Field Service Job In Carter Lake | F21: Healthcare Services | G21: IA | H21: $60K-$80K
A22: 4053 | C22: Full Time | D22: Houston, TX | E22: Business & Strategy Analyst Job In Houston | F22: Legal Services | G22: TX
A23: 1777 | C23: Contract/Temporary | D23: Houston, TX 77027 | E23: Real Estate Underwriter -Jr Job In Houston | F23: Accounting and Auditing Services | G23: TX
A24: 1795 | C24: Full Time | D24: La Porte 46350 | E24: Combat Engineer - Construction And Engineering Specialist Job In La Porte Body { Margin:Px; Overflow: Visible !Important; } #Ejb_Header { Color: #; Font-Family: Verdana | F24: Healthcare Services
A25: 2468 | C25: Full Time | D25: Denver, CO 80215 | E25: Estimator - Construction Job In Denver | F25: Healthcare Services | G25: CO
A26: 6478 | C26: Full Time | D26: Houston, TX | E26: Construction Healthcare Superintendent / Hospital Superintendent Job In Houston | F26: Construction - Residential & Commercial/Office | G26: TX
A27: 300 | C27: Full Time | D27: San Carlos, CA 94070 | E27: Biomedical Engineering Director Job In San Carlos | F27: Engineering Services | G27: CA
A28: 1717 | C28: Full Time | D28: Denver, CO | E28: At&T Business Sales Leadership Development Program Bilingual Spanish Job In Denver | F28: Healthcare Services | G28: CO
A29: 3266 | C29: Full Time | D29: Houston, TX 77040 | E29: Traveling Customer Training Professional Job In Houston | F29: AllComputer SoftwareComputer/IT Services | G29: TX
A30: 2018 | C30: Full Time | D30: Houston, TX | E30: Resident Care Specialist | F30: Healthcare Services | G30: TX
A31: 2009 | B31: 70000 | C31: Full Time | D31: Sr. Process Engineer, Manufacturing | E31: Sr. Process Engineer | F31: Chicago, IL | H31: $60K-$80K
A32: 1440 | B32: 62 | C32: Contract/Temporary | D32: Mounds View, MN 55112 | E32: Mechanical Engineer - Fea/Mechanical Modeling/Product Development Job In Mounds View | F32: Healthcare Services | G32: MN | H32: <$40K
A33: 630 | C33: Full Time | D33: Knoxville, TN | E33: Recreation Therapy Assistant Job In Knoxville | F33: Healthcare Services | G33: TN
A34: 3524 | B34: 75000 | C34: Full Time | D34: Aurora, IL 60502 | E34: Machine Control Systems Engineer - Bsee Job In Aurora | F34: Healthcare Services | G34: IL | H34: $60K-$80K
A35: 471 | C35: Full Time | D35: Denver, CO 80202 | E35: Equipment Operator Job In Denver | F35: Healthcare Services | G35: CO
A36: 2487 | C36: Full Time | D36: Saint Louis, MO 63116 | E36: Associate Product Developer Job In Saint Louis | F36: Manufacturing - Other | G36: MO
A37: 2432 | C37: Full Time | D37: Washington, DC | E37: Technical Writer W/ Ts Clearance Job In Washington | F37: Computer/IT Services | G37: DC
A38: 2837 | B38: 68000 | C38: Contract/Temporary | D38: RF System Technician, Field Service | E38: Rf System Technician | F38: Oklahoma City, OK | H38: $60K-$80K
A39: 1053 | C39: Full Time | D39: Monroeville, PA 15146 | E39: Quality Engineer Job In Monroeville | F39: Aerospace and Defense | G39: PA
A40: 3122 | C40: Contract/Temporary | D40: Bi-Lingual Editorial Strategist | E40: Bi-Lingual Editorial Strategist Job In San Francisco | F40: San Francisco, CA
...
